Workbook
Name acc_base: '4_Scenarios'!$K$9
Name acc_elasticity: '4_Scenarios'!$K$10
Name acq_rate_base: '5_ROI_NPV'!$L$7
Name assume_accept: '7_Output_Summary'!$C$54
Name assume_acq: '7_Output_Summary'!$C$53
Name assume_attr: '7_Output_Summary'!$C$52
Name assume_mr: '7_Output_Summary'!$C$55
Name assume_spend: '7_Output_Summary'!$C$51
Name assume_wacc: '7_Output_Summary'!$C$56
Name attain_baseline: '4_Scenarios'!$K$4
Name attrition: '1_Assumptions'!$D$17
Name benefit_cost_total: '7_Output_Summary'!$C$16
Name benefit_face_summary: '7_Output_Summary'!$C$18
Name benefit_headroom: '3_Benefit'!$D$40
Name benefit_headroom_summary: '7_Output_Summary'!$C$17
Name benefit_leverage: '3_Benefit'!$D$41
Name benefit_leverage_summary: '7_Output_Summary'!$C$19
Name bizdev_rate: '2_Baseline_PnL'!$M$5
Name bonus_renewal: '1_Assumptions'!$D$20
Name bonus_welcome: '1_Assumptions'!$D$19
Name breakeven_summary: '7_Output_Summary'!$C$38
Name cac: '2_Baseline_PnL'!$M$9
Name cac_life: '2_Baseline_PnL'!$M$10
Name card_base: '1_Assumptions'!$D$10
Name cards: '7_Output_Summary'!$C$5
Name cards_incr_y1: '5_ROI_NPV'!$E$9
Name cards_y0: '5_ROI_NPV'!$D$48
Name cards_y0_out: '7_Output_Summary'!$C$24
Name cards_y1: '5_ROI_NPV'!$E$7
Name cards_y5: '5_ROI_NPV'!$D$49
Name cards_y5_cf: '5_ROI_NPV'!$D$50
Name cards_y5_cf_out: '7_Output_Summary'!$C$26
Name cards_y5_out: '7_Output_Summary'!$C$25
Name cl_rate: '2_Baseline_PnL'!$M$6
Name cms_rate: '2_Baseline_PnL'!$M$13
Name contrib_incr: '5_ROI_NPV'!$D$57
Name contrib_post: '5_ROI_NPV'!$D$56
Name contrib_pre: '5_ROI_NPV'!$D$55
Name contrib_pre_summary: '7_Output_Summary'!$C$27
Name cost_ceiling: '1_Assumptions'!$D$18
Name delta_breakeven: '5_ROI_NPV'!$D$59
Name delta_gap: '5_ROI_NPV'!$D$60
Name disc_rate: '2_Baseline_PnL'!$M$3
Name discount_rate_cof: '1_Assumptions'!$D$11
Name emi_margin_net: '1_Assumptions'!$D$9
Name emi_penetration: '1_Assumptions'!$D$8
Name fcf_cumul_summary: '7_Output_Summary'!$C$30
Name fcf_percard_summary: '7_Output_Summary'!$C$29
Name fee_annual: '1_Assumptions'!$D$3
Name fee_baseline: '4_Scenarios'!$K$3
Name fee_delta: '7_Output_Summary'!$C$8
Name fee_gain_summary: '7_Output_Summary'!$C$28
Name fee_gross: '1_Assumptions'!$D$5
Name fee_post: '7_Output_Summary'!$C$7
Name fee_pre: '7_Output_Summary'!$C$6
Name float_days: '2_Baseline_PnL'!$M$8
Name fraud_rate: '2_Baseline_PnL'!$M$7
Name fx_markup: '2_Baseline_PnL'!$M$4
Name gap_summary: '7_Output_Summary'!$C$39
Name gst_rate: '1_Assumptions'!$D$4

Sheet 1_Assumptions
B1: PLATINUM 365 — ASSUMPTIONS REGISTRY | F1: Column C = model reference ID. See Tab notes (col F/6) for sourcing of each figure.
B2: CONTROL BLOCK
B3: Annual fee (ex-GST) | C3: A1 | D3: 68000 | E3: INPUT | F3: Central case; PS S3 states ₹60K — Tab 6 justifies ₹66K
B4: GST on fee | C4: A2 | D4: 0.18 | E4: FIXED | F4: Statute, pass-through — not issuer revenue
B5: Gross billed to member | C5: A3 | D5: =D3*(1+D4) -> 80240 | E5: FORMULA | F5: Formula
B6: Spend mix (intl/trv/din/oth) | C6: B5 | D6: 0.15 | E6: 0.1 | F6: 0.12 | G6: 0.63 | H6: =SUM(D6:G6) -> 1 | I6: =IF(ABS(H6-1)<0.0001,"✓ sums to 100%","✗ CHECK MIX") -> ✓ sums to 100%
B7: Scenario selector | C7: — | D7: Base | E7: INPUT | F7: Drives Tabs 4–6
B8: EMI penetration % | C8: — | D8: 0.06 | E8: INPUT | F8: Of ≥₹19L segments only
B9: EMI net margin % | C9: C6 | D9: 0.045 | E9: INPUT | F9: Charge card — bounded book, not 8.1%
B10: Card base size | C10: — | D10: 40000 | E10: INPUT | F10: Bottom-up 38.5K / top-down 30–55K
B11: Cost of funds | C11: D12 | D11: 0.058 | E11: FIXED | F11: AEBC business ratios
B12: Risk premium | C12: — | D12: 0.025 | E12: INPUT | F12: Amex-specific
B13: Discount rate (WACC) | C13: — | D13: =D11+D12 -> 0.083 | E13: FORMULA | F13: Formula — used in Tab 5 NPV
B14: MR cost per point | C14: D1 | D14: 0.26 | E14: INPUT | F14: Derived, AEBC Note 12(p); range ₹0.21–0.33
B15: MR blended multiplier | C15: B4 | D15: 1.9 | E15: INPUT | F15: From A5 + spend mix
B16: Ultimate redemption rate | C16: D4 | D16: 0.96 | E16: FIXED | F16: AR2025
B17: Baseline attrition | C17: — | D17: 0.1 | E17: INPUT | F17: Pre-redesign annual churn
B18: Incremental benefit ceiling | C18: A12 | D18: 20000 | E18: FIXED | F18: PS S4 constraint 2 — HARD
B19: Welcome bonus (annual) | C19: A13 | D19: 25000 | E19: INPUT
B20: Renewal bonus (annual) | C20: A14 | D20: 10000 | E20: INPUT
B21: ID | C21: Category | D21: Parameter | E21: Value | F21: Unit | G21: Source | H21: Conf | I21: Note
B22: — PART A — CARD SPECIFICATION —
B23: A1 | C23: Card spec | D23: Annual fee (ex-GST) | E23: ₹60,000 (range ₹50–70K) | F23: ₹ | G23: PS S3 | H23: H | I23: Central case runs ₹66K — see Tab 6
B24: A2 | C24: Card spec | D24: GST | E24: 18%, pass-through | F24: % | G24: Statute | H24: H | I24: Not issuer revenue
B25: A3 | C25: Card spec | D25: Gross billed to customer | E25: ₹70,800 @A1; ₹77,880 @₹66K | F25: ₹ | G25: A1×1.18 | H25: M
B26: A4 | C26: Card spec | D26: Base earn | E26: 1 pt / ₹50 | F26: pts | G26: PS S3 | H26: H
B27: A5 | C27: Card spec | D27: Multipliers | E27: 5x intl, 3x travel portal, 2x dining >₹2K | F27: × | G27: PS S3 | H27: H
B28: A6 | C28: Card spec | D28: Point face value | E28: ₹0.50 transfer / ₹0.25 stmt credit | F28: ₹ | G28: PS S3 | H28: H
B29: A7 | C29: Card spec | D29: Welcome bonus | E29: 25,000 pts | F29: pts | G29: PS S3 | H29: H | I29: Amortised 5yr
B30: A8 | C30: Card spec | D30: Renewal bonus | E30: 10,000 pts | F30: pts | G30: PS S3 | H30: H | I30: Amortised 5yr
B31: A9 | C31: Card spec | D31: Milestone threshold | E31: ₹19,00,000 | F31: ₹ | G31: PS S3 | H31: H | I31: Anchors blended mean
B32: A10 | C32: Card spec | D32: Domestic lounge | E32: 8 visits/yr | F32: visits | G32: PS S3 | H32: H
B33: A11 | C33: Card spec | D33: Segment income floor | E33: ₹25L household | F33: ₹ | G33: PS S4 | H33: H
B34: A12 | C34: Card spec | D34: Incremental benefit ceiling | E34: ≤₹20,000/card/yr | F34: ₹ | G34: PS S4 | H34: H | I34: HARD CONSTRAINT
B35: — PART B — SPEND DISTRIBUTION —
B36: B1 | C36: Spend | D36: Blended mean spend | E36: ₹19.0L | F36: ₹ | G36: Anchored to A9 | H36: A
B37: B2 | C37: Spend | D37: Distribution | E37: 8/13/19/28/45L @ 18/27/30/17/8% | F37: ₹/% | G37: Derived | H37: A
B38: B3 | C38: Spend | D38: Milestone attainment | E38: 55% | F38: % | G38: From B2 | H38: M
B39: B4 | C39: Spend | D39: Blended earn multiplier | E39: 1.90× | F39: × | G39: A5 + spend mix | H39: A
B40: B5 | C40: Spend | D40: Spend mix | E40: 15/10/12/63% | F40: % | G40: Assumption | H40: A | I40: Intl/travel/dining/other
...

Sheet 2_Baseline_PnL
B1: TAB 2 — BASELINE P&L (per card, pre-redesign)
L2: RATES USED
B3: Line item | C3: ID | D3: Underused | E3: Core | F3: Milestone | G3: High | H3: Whale | I3: BLENDED | J3: % of BB | L3: Discount rate | M3: 0.0224
B4: Segment weight | C4: B2 | D4: 0.18 | E4: 0.27 | F4: 0.3 | G4: 0.17 | H4: 0.08 | I4: =SUM(D4:H4) -> 1 | L4: FX markup | M4: 0
B5: Annual spend per card | C5: B2 | D5: 800000 | E5: 1300000 | F5: 1900000 | G5: 2800000 | H5: 4500000 | I5: =SUMPRODUCT($D$4:$H$4,D5:H5) -> 1901000 | L5: BizDev rate | M5: 0.0039
B6: Milestone hit (≥₹19L) | C6: A9 | D6: no | E6: no | F6: YES | G6: YES | H6: YES | L6: Credit loss rate | M6: 0.0168
B7: Avg receivable (float) | C7: — | D7: =D5*float_days/365 -> 98630.137 | E7: =E5*float_days/365 -> 160273.97 | F7: =F5*float_days/365 -> 234246.58 | G7: =G5*float_days/365 -> 345205.48 | H7: =H5*float_days/365 -> 554794.52 | I7: =SUMPRODUCT($D$4:$H$4,D7:H7) -> 234369.86 | L7: Fraud rate | M7: 0.0005
L8: Float days | M8: 45
B9: SPEND SPLIT | L9: CAC | M9: 43500
B10: International | C10: B5 | D10: =D5*mix_intl -> 120000 | E10: =E5*mix_intl -> 195000 | F10: =F5*mix_intl -> 285000 | G10: =G5*mix_intl -> 420000 | H10: =H5*mix_intl -> 675000 | I10: =SUMPRODUCT($D$4:$H$4,D10:H10) -> 285150 | J10: =I10/$I$5 -> 0.15 | L10: CAC life (yrs) | M10: 5
B11: Travel portal | C11: B5 | D11: =D5*mix_travel -> 80000 | E11: =E5*mix_travel -> 130000 | F11: =F5*mix_travel -> 190000 | G11: =G5*mix_travel -> 280000 | H11: =H5*mix_travel -> 450000 | I11: =SUMPRODUCT($D$4:$H$4,D11:H11) -> 190100 | J11: =I11/$I$5 -> 0.1 | L11: New cards % / yr | M11: 0.08
B12: Dining >₹2K | C12: B5 | D12: =D5*mix_dining -> 96000 | E12: =E5*mix_dining -> 156000 | F12: =F5*mix_dining -> 228000 | G12: =G5*mix_dining -> 336000 | H12: =H5*mix_dining -> 540000 | I12: =SUMPRODUCT($D$4:$H$4,D12:H12) -> 228120 | J12: =I12/$I$5 -> 0.12 | L12: Layer 1 benefit cost | M12: 38900
B13: Other | C13: B5 | D13: =D5*mix_other -> 504000 | E13: =E5*mix_other -> 819000 | F13: =F5*mix_other -> 1197000 | G13: =G5*mix_other -> 1764000 | H13: =H5*mix_other -> 2835000 | I13: =SUMPRODUCT($D$4:$H$4,D13:H13) -> 1197630 | J13: =I13/$I$5 -> 0.63 | L13: CMS rate (alt method) | M13: 0.0036
B15: REWARDS POINTS EARNED
B16: Base + multiplier points | C16: A4/B4 | D16: =D5*mr_multiplier/50 -> 30400 | E16: =E5*mr_multiplier/50 -> 49400 | F16: =F5*mr_multiplier/50 -> 72200 | G16: =G5*mr_multiplier/50 -> 106400 | H16: =H5*mr_multiplier/50 -> 171000 | I16: =SUMPRODUCT($D$4:$H$4,D16:H16) -> 72238
B17: Welcome bonus (amortised) | C17: A7 | D17: =bonus_welcome/12 -> 2083.3333 | E17: =bonus_welcome/12 -> 2083.3333 | F17: =bonus_welcome/12 -> 2083.3333 | G17: =bonus_welcome/12 -> 2083.3333 | H17: =bonus_welcome/12 -> 2083.3333 | I17: =SUMPRODUCT($D$4:$H$4,D17:H17) -> 2083.3333
B18: Renewal bonus (amortised) | C18: A8 | D18: =bonus_renewal/12 -> 833.33333 | E18: =bonus_renewal/12 -> 833.33333 | F18: =bonus_renewal/12 -> 833.33333 | G18: =bonus_renewal/12 -> 833.33333 | H18: =bonus_renewal/12 -> 833.33333 | I18: =SUMPRODUCT($D$4:$H$4,D18:H18) -> 833.33333
B19: Total points / yr | C19: — | D19: =SUM(D16:D18) -> 33316.667 | E19: =SUM(E16:E18) -> 52316.667 | F19: =SUM(F16:F18) -> 75116.667 | G19: =SUM(G16:G18) -> 109316.67 | H19: =SUM(H16:H18) -> 173916.67 | I19: =SUMPRODUCT($D$4:$H$4,D19:H19) -> 75154.667
B21: REVENUE
B22: Annual fee (ex-GST) | C22: A1 | D22: =fee_annual -> 68000 | E22: =fee_annual -> 68000 | F22: =fee_annual -> 68000 | G22: =fee_annual -> 68000 | H22: =fee_annual -> 68000 | I22: =SUMPRODUCT($D$4:$H$4,D22:H22) -> 68000
B23: Discount revenue | C23: C1 | D23: =D5*disc_rate -> 17920 | E23: =E5*disc_rate -> 29120 | F23: =F5*disc_rate -> 42560 | G23: =G5*disc_rate -> 62720 | H23: =H5*disc_rate -> 100800 | I23: =SUMPRODUCT($D$4:$H$4,D23:H23) -> 42582.4 | J23: =I23/$I$5 -> 0.0224
B24: FX markup revenue | C24: C4 | D24: =D5*mix_intl*fx_markup -> 0 | E24: =E5*mix_intl*fx_markup -> 0 | F24: =F5*mix_intl*fx_markup -> 0 | G24: =G5*mix_intl*fx_markup -> 0 | H24: =H5*mix_intl*fx_markup -> 0 | I24: =SUMPRODUCT($D$4:$H$4,D24:H24) -> 0
B25: EMI net interest income | C25: C6 | D25: =IF(D5>=1900000,D5*emi_penetration*emi_margin_net,0) -> 0 | E25: =IF(E5>=1900000,E5*emi_penetration*emi_margin_net,0) -> 0 | F25: =IF(F5>=1900000,F5*emi_penetration*emi_margin_net,0) -> 5130 | G25: =IF(G5>=1900000,G5*emi_penetration*emi_margin_net,0) -> 7560 | H25: =IF(H5>=1900000,H5*emi_penetration*emi_margin_net,0) -> 12150 | I25: =SUMPRODUCT($D$4:$H$4,D25:H25) -> 3796.2
B26: TOTAL REVENUE | C26: — | D26: =SUM(D22:D25) -> 85920 | E26: =SUM(E22:E25) -> 97120 | F26: =SUM(F22:F25) -> 115690 | G26: =SUM(G22:G25) -> 138280 | H26: =SUM(H22:H25) -> 180950 | I26: =SUMPRODUCT($D$4:$H$4,D26:H26) -> 114378.6 | J26: =I26/$I$5 -> 0.060167596
B28: COST
B29: MR rewards (points × cpp × URR) | C29: D1/D4 | D29: =D19*mr_cpp*redemption_rate -> 8315.84 | E29: =E19*mr_cpp*redemption_rate -> 13058.24 | F29: =F19*mr_cpp*redemption_rate -> 18749.12 | G29: =G19*mr_cpp*redemption_rate -> 27285.44 | H29: =H19*mr_cpp*redemption_rate -> 43409.6 | I29: =SUMPRODUCT($D$4:$H$4,D29:H29) -> 18758.605 | J29: =I29/$I$5 -> 0.0098677563
B30: Layer 1 benefits (bottom-up) | C30: L1.x | D30: =layer1_cost -> 38900 | E30: =layer1_cost -> 38900 | F30: =layer1_cost -> 38900 | G30: =layer1_cost -> 38900 | H30: =layer1_cost -> 38900 | I30: =SUMPRODUCT($D$4:$H$4,D30:H30) -> 38900 | J30: =I30/$I$5 -> 0.020462914
B31: Business development | C31: D7 | D31: =D5*bizdev_rate -> 3120 | E31: =E5*bizdev_rate -> 5070 | F31: =F5*bizdev_rate -> 7410 | G31: =G5*bizdev_rate -> 10920 | H31: =H5*bizdev_rate -> 17550 | I31: =SUMPRODUCT($D$4:$H$4,D31:H31) -> 7413.9 | J31: =I31/$I$5 -> 0.0039
B32: Acquisition (amortised) | C32: D8 | D32: =cac/cac_life*new_card_pct -> 696 | E32: =cac/cac_life*new_card_pct -> 696 | F32: =cac/cac_life*new_card_pct -> 696 | G32: =cac/cac_life*new_card_pct -> 696 | H32: =cac/cac_life*new_card_pct -> 696 | I32: =SUMPRODUCT($D$4:$H$4,D32:H32) -> 696
B33: Credit loss (on receivables) | C33: D9 | D33: =D7*cl_rate -> 1656.9863 | E33: =E7*cl_rate -> 2692.6027 | F33: =F7*cl_rate -> 3935.3425 | G33: =G7*cl_rate -> 5799.4521 | H33: =H7*cl_rate -> 9320.5479 | I33: =SUMPRODUCT($D$4:$H$4,D33:H33) -> 3937.4137 | J33: =I33/$I$5 -> 0.0020712329
B34: Fraud loss | C34: D11 | D34: =D5*fraud_rate -> 400 | E34: =E5*fraud_rate -> 650 | F34: =F5*fraud_rate -> 950 | G34: =G5*fraud_rate -> 1400 | H34: =H5*fraud_rate -> 2250 | I34: =SUMPRODUCT($D$4:$H$4,D34:H34) -> 950.5
B35: Cost of funds (on receivables) | C35: D12 | D35: =D7*discount_rate_cof -> 5720.5479 | E35: =E7*discount_rate_cof -> 9295.8904 | F35: =F7*discount_rate_cof -> 13586.301 | G35: =G7*discount_rate_cof -> 20021.918 | H35: =H7*discount_rate_cof -> 32178.082 | I35: =SUMPRODUCT($D$4:$H$4,D35:H35) -> 13593.452 | J35: =I35/$I$5 -> 0.0071506849
B36: TOTAL BASELINE COST | C36: — | D36: =SUM(D29:D35) -> 58809.374 | E36: =SUM(E29:E35) -> 70362.733 | F36: =SUM(F29:F35) -> 84226.764 | G36: =SUM(G29:G35) -> 105022.81 | H36: =SUM(H29:H35) -> 144304.23 | I36: =SUMPRODUCT($D$4:$H$4,D36:H36) -> 84249.871 | J36: =I36/$I$5 -> 0.044318711
B38: OUTPUT
B39: Baseline contribution | C39: — | D39: =D26-D36 -> 27110.626 | E39: =E26-E36 -> 26757.267 | F39: =F26-F36 -> 31463.236 | G39: =G26-G36 -> 33257.19 | H39: =H26-H36 -> 36645.77 | I39: =SUMPRODUCT($D$4:$H$4,D39:H39) -> 30128.729
B40: Contribution margin % | C40: — | D40: =D39/D26 -> 0.31553335 | E40: =E39/E26 -> 0.27550728 | F40: =F39/F26 -> 0.27196159 | G40: =G39/G26 -> 0.24050615 | H40: =H39/H26 -> 0.20251876 | I40: =I39/I26 -> 0.26341229
B42: VALIDATION GATES
B43: Rewards as % of spend (D5 gate) | C43: D5 | I43: =I29/I5 -> 0.0098677563 | J43: =IF(AND(I43>=0.0095,I43<=0.0105),"✓ PASS 0.95–1.05%","✗ FAIL — check B4/D1") -> ✓ PASS 0.95–1.05%
B44: Discount revenue ÷ spend | I44: =I23/I5 -> 0.0224 | J44: =IF(ABS(I44-disc_rate)<0.00001,"✓ PASS","✗ FAIL") -> ✓ PASS
B45: Blended spend = ₹19.0L (A9 anchor) | I45: =I5 -> 1901000 | J45: =IF(ABS(I45-1900000)<15000,"✓ PASS","✗ FAIL") -> ✓ PASS
...

Sheet 3_Benefit
B1: PLATINUM 365 — BENEFIT COST ENGINE | G1: Net cost = unit x utilisation x (1 - co-fund). Only Layer 2 + Layer 3 count vs the Rs.20K ceiling.
B3: ID | C3: Benefit | D3: Layer | E3: Status | F3: Pillar | G3: Face value | H3: Unit cost | I3: Util % | J3: Co-fund % | K3: Net cost | L3: Cost if activated | M3: Counts vs Rs.20K? | N3: Tightening / basis
B4: LAYER 1 — RETAINED · baseline stack · does NOT count vs the Rs.20K ceiling
B5: L1.1 | C5: Unlimited lounge access | D5: 1 | E5: RETAIN | F5: Travel | G5: 8000 | H5: 800 | I5: 1 | J5: 0 | K5: =H5*I5*(1-J5) -> 800 | L5: =K5 -> 800 | M5: N | N5: Partner subsidy rate
B6: L1.2 | C6: 4 hotel elite statuses | D6: 1 | E6: RETAIN | F6: Travel | G6: 6000 | H6: 450 | I6: 1 | J6: 0 | K6: =H6*I6*(1-J6) -> 450 | L6: =K6 -> 450 | M6: N | N6: Negotiated, status-only
B7: L1.3 | C7: Fine Hotels & Resorts credit | D7: 1 | E7: RETAIN | F7: Travel | G7: 44300 | H7: 14800 | I7: 1 | J7: 0 | K7: =H7*I7*(1-J7) -> 14800 | L7: =K7 -> 14800 | M7: N | N7: 75% util x co-fund, already net
B8: L1.4 | C8: Golf (unlimited) | D8: 1 | E8: RETAIN | F8: Lifestyle | G8: 3000 | H8: 500 | I8: 1 | J8: 0 | K8: =H8*I8*(1-J8) -> 500 | L8: =K8 -> 500 | M8: N
B9: L1.5 | C9: Taj 25% discount | D9: 1 | E9: RETAIN | F9: Lifestyle | G9: 2500 | H9: 0 | I9: 1 | J9: 0 | K9: =H9*I9*(1-J9) -> 0 | L9: =K9 -> 0 | M9: N | N9: Revenue-neutral to issuer
B10: L1.6 | C10: Dining perks (EazyDiner + PVR) | D10: 1 | E10: RETAIN | F10: Dining | G10: 3600 | H10: 1200 | I10: 1 | J10: 0 | K10: =H10*I10*(1-J10) -> 1200 | L10: =K10 -> 1200 | M10: N
B11: L1.7 | C11: Welcome vouchers (amortised) | D11: 1 | E11: RETAIN | F11: Acquisition | G11: 12000 | H11: 12000 | I11: 1 | J11: 0 | K11: =H11*I11*(1-J11) -> 12000 | L11: =K11 -> 12000 | M11: N | N11: 5-yr amortisation
B12: L1.8 | C12: Renewal vouchers @ Rs.20L | D12: 1 | E12: RETAIN | F12: Retention | G12: 7000 | H12: 3850 | I12: 1 | J12: 0 | K12: =H12*I12*(1-J12) -> 3850 | L12: =K12 -> 3850 | M12: N | N12: 55% attainment
B13: L1.9 | C13: Rewards program (1pt/Rs.50) | D13: 1 | E13: RETAIN | F13: Earn | G13: 9880 | H13: 0 | I13: 1 | J13: 0 | K13: =H13*I13*(1-J13) -> 0 | L13: =K13 -> 0 | M13: N | N13: COSTED IN TAB 2 (MR line) — zero here to avoid double-count
B14: L1.10 | C14: Charge card basics | D14: 1 | E14: RETAIN | F14: Protection | G14: 4200 | H14: 4200 | I14: 1 | J14: 0 | K14: =H14*I14*(1-J14) -> 4200 | L14: =K14 -> 4200 | M14: N | N14: No spend cap, zero forex, insurance, transfers, 24/7 concierge
B15: L1.11 | C15: Digital-First Concierge | D15: 1 | E15: RETAIN | F15: Service | G15: 2200 | H15: 1100 | I15: 1 | J15: 0 | K15: =H15*I15*(1-J15) -> 1100 | L15: =K15 -> 1100 | M15: N | N15: Moved from L2.4 — channel upgrade to an existing L1 concierge, not a new benefit
C16: LAYER 1 SUBTOTAL (retained) | G16: =SUM(G5:G15) -> 102680 | K16: =SUM(K5:K15) -> 38900 | L16: =K16 -> 38900
B18: LAYER 2 — ALWAYS-ON · 100% of card base · COUNTS vs ceiling
B19: L2.1 | C19: Value Ledger | D19: 2 | E19: NEW | F19: Engagement | G19: 2500 | H19: 1200 | I19: 1 | J19: 0 | K19: =H19*I19*(1-J19) -> 1200 | L19: =H19*I19*(1-J19) -> 1200 | M19: Y | N19: Infra, auto-on, 100% util by design
B20: L2.2 | C20: Progressive Milestone Ladder | D20: 2 | E20: NEW | F20: Engagement | G20: 8000 | H20: 6000 | I20: 0.495 | J20: 0 | K20: =H20*I20*(1-J20) -> 2970 | L20: =H20*I20*(1-J20) -> 2970 | M20: Y | N20: Calendar-yr spend only (no rolling 12m) | 90-day voucher expiry | partner-brand redemption only. Util = 55% attain x 90% redeem
B21: L2.3 | C21: Big-Ticket Digital Advantage | D21: 2 | E21: NEW | F21: Digital | G21: 3500 | H21: 1600 | I21: 0.45 | J21: 0.5 | K21: =H21*I21*(1-J21) -> 360 | L21: =H21*I21*(1-J21) -> 360 | M21: Y | N21: Max 2 PPC claims/yr | Rs.2L cap per claim | app-registered pre-checkout
C22: LAYER 2 SUBTOTAL (always-on) | G22: =SUM(G19:G21) -> 14000 | K22: =SUM(K19:K21) -> 4530 | L22: =SUM(L19:L21) -> 4530
B24: LAYER 3 — CHOICE MODULES · 4 active / 2 reserve · COUNTS vs ceiling · flip Status to re-run the swap
B25: M1 | C25: Premium Ground Mobility | D25: 3 | E25: RESERVE | F25: Lifestyle | G25: 7200 | H25: 4800 | I25: 0.6 | J25: 0.4 | K25: =IF($E25="ACTIVE",H25*I25*(1-J25),0) -> 0 | L25: =H25*I25*(1-J25) -> 1728 | M25: Y | N25: RESERVE — Uber Black, activates on swap
B26: M2 | C26: Culinary Access | D26: 3 | E26: ACTIVE | F26: Lifestyle | G26: 9600 | H26: 5400 | I26: 0.75 | J26: 0.35 | K26: =IF($E26="ACTIVE",H26*I26*(1-J26),0) -> 2632.5 | L26: =H26*I26*(1-J26)*0.5 -> 1316.25 | M26: Y | N26: Held tables + Rs.800/mo credit; restaurant co-fund 35% | Slot share 0.5 applied — member activates 2 of 4 Layer-3 modules
B27: M3 | C27: Luxury Digital Retail | D27: 3 | E27: ACTIVE | F27: Lifestyle | G27: 12000 | H27: 6600 | I27: 0.55 | J27: 0.4 | K27: =IF($E27="ACTIVE",H27*I27*(1-J27),0) -> 2178 | L27: =H27*I27*(1-J27)*0.5 -> 1089 | M27: Y | N27: Rs.1,000/mo budget; marketplace co-fund 40% | Slot share 0.5 applied — member activates 2 of 4 Layer-3 modules
B28: M4 | C28: Preventive Health | D28: 3 | E28: ACTIVE | F28: Wellness | G28: 8000 | H28: 4200 | I28: 0.7 | J28: 0.3 | K28: =IF($E28="ACTIVE",H28*I28*(1-J28),0) -> 2058 | L28: =H28*I28*(1-J28)*0.5 -> 1029 | M28: Y | N28: 2 panels + 10 teleconsults, hard-bounded; lab co-fund 30% | Slot share 0.5 applied — member activates 2 of 4 Layer-3 modules
B29: M5 | C29: Culture & Events | D29: 3 | E29: RESERVE | F29: Lifestyle | G29: 9800 | H29: 5400 | I29: 0.5 | J29: 0.5 | K29: =IF($E29="ACTIVE",H29*I29*(1-J29),0) -> 0 | L29: =H29*I29*(1-J29) -> 1350 | M29: Y | N29: RESERVE — Culture & Events, activates on swap
B30: M6 | C30: Premium Household Services | D30: 3 | E30: ACTIVE | F30: Lifestyle | G30: 9600 | H30: 5800 | I30: 0.65 | J30: 0.35 | K30: =IF($E30="ACTIVE",H30*I30*(1-J30),0) -> 2450.5 | L30: =H30*I30*(1-J30)*0.5 -> 1225.25 | M30: Y | N30: Rs.800/mo single provider; co-fund 35% | Slot share 0.5 applied — member activates 2 of 4 Layer-3 modules
C31: LAYER 3 SUBTOTAL (active only) | G31: =SUMIF($E25:$E30,"ACTIVE",G25:G30) -> 39200 | K31: =SUM(K25:K30) -> 9319 | L31: =SUM(L25:L30) -> 7737.5
C32: Reserve pool (M1 + M5) — funded from headroom on swap | K32: =SUMIF($E25:$E30,"RESERVE",L25:L30) -> 3078 | N32: Cost only if a member swaps into them; the swap-out releases the module it replaces
B34: ROLLUP — INCREMENTAL BENEFIT COST vs THE Rs.20,000 CEILING
B35: Item | C35: Face value Rs. | D35: Issuer net cost Rs.
B36: Layer 2 (always-on) | C36: =G22 -> 14000 | D36: =K22 -> 4530
B37: Layer 3 (4 modules active) | C37: =G31 -> 39200 | D37: =K31 -> 9319
B38: TOTAL NEW BENEFIT (counts vs ceiling) | C38: =C36+C37 -> 53200 | D38: =D36+D37 -> 13849
B39: Ceiling (PS S4 constraint 2) | D39: =cost_ceiling -> 20000
B40: HEADROOM | D40: =D39-D38 -> 6151
B41: Leverage (face / cost) | D41: =C38/D38 -> 3.8414326
B42: Layer 1 retained cost (memo — reconciles to Tab 2 Layer 1 line) | D42: =K16 -> 38900
B44: SEGMENT-LEVEL EXPOSURE — utilisation scales with spend tier; utilisation capped at 100%
B45: Benefit (counting rows only) | C45: Unit x (1-cofund) | D45: Underused Rs.8L | E45: Core Rs.13L | F45: Milestone Rs.19L | G45: High Rs.28L | H45: Whale Rs.45L
...

Sheet 3B_Reallocation
B1: REALLOCATION REGISTER — Layer 1 Redesign
B3: ID | C3: Benefit Name | D3: Current Cost | E3: Action | F3: Cost Freed | G3: PS Constraint 4? | H3: Reason
B4: L1.1 | C4: Unlimited lounge | D4: 800 | E4: KEEP | F4: 0 | G4: ✓ YES | H4: PS Constraint 4: travel benefits must continue
B5: L1.2 | C5: 4 hotel elite statuses | D5: 450 | E5: KEEP | F5: 0 | G5: ✓ YES | H5: PS Constraint 4: travel benefits must continue
B6: L1.3 | C6: Fine Hotels & Resorts credit | D6: 14800 | E6: RESIZE 50% | F6: 7400 | G6: ✓ YES | H6: Oversized for affluent; 75% util but low booking; gate at ₹7.4K
B7: L1.4 | C7: Golf (unlimited) | D7: 8000 | E7: RETIRE | F7: 3000 | G7: ✓ YES | H7: Not a travel benefit; <2% utilization; frees budget
B8: L1.6 | C8: Dining perks | D8: 1200 | E8: KEEP | F8: 0 | G8: ✓ YES | H8: Superseded by M2 Culinary in L3, but keep L1 version
B9: L1.7 | C9: Welcome vouchers | D9: 12000 | E9: KEEP | F9: 0 | G9: ✓ YES | H9: Acquisition lever; optional resize to 50% (₹6K) if needed
B10: L1.8 | C10: Renewal vouchers | D10: 3850 | E10: SUPERSEDE | F10: 3850 | G10: ✓ YES | H10: Replaced by L2.2 Milestone Ladder (no cliff, smoother engagement)
B11: L1.10 | C11: Charge card basics | D11: 4200 | E11: KEEP | F11: 0 | G11: ✓ YES | H11: Essential; counts toward Layer 1
B12: L1.11 | C12: Digital-First Concierge | D12: 1100 | E12: KEEP | F12: 0 | G12: ✓ YES | H12: Essential; counts toward Layer 1
B13: TOTAL RECLAIMED | F13: 14250
B15: Layer 1 total (before reallocation) | D15: =SUM(D4:D12) -> 46400
B16: Layer 1 total (after reallocation) | D16: =D15-F13 -> 32150
B18: VALIDATION: PS Constraint 4 — Travel benefits retained? | D18: =IF(AND(COUNTIF(G4:G14,"✓ YES")>=2), "PASS — Lounge + Hotel kept", "FAIL") -> PASS — Lounge + Hotel kept

Sheet 4_Scenarios
B1: PLATINUM 365 — BEHAVIOURAL SCENARIOS | D1: SELECTED column follows the Tab 1 scenario dropdown
J2: SCENARIO-INDEPENDENT INPUTS
B3: BLOCK A — LEVER ASSUMPTIONS | J3: Pre-redesign fee (baseline) | K3: 60000
B4: Lever | C4: ID | D4: Conservative | E4: Base | F4: Bull | G4: SELECTED | H4: Evidence | J4: Milestone attainment baseline | K4: 0.55
B5: Spend uplift vs baseline | C5: S1 | D5: -0.05 | E5: 0.08 | F5: 0.15 | G5: =INDEX(D5:F5,MATCH(scenario,$D$4:$F$4,0)) -> 0.08 | H5: US Platinum Sept-2025 reprice: +12-18% Y1 spend | J5: Module utilisation baseline | K5: 0.6
B6: Milestone attainment | C6: S2 | D6: 0.5 | E6: 0.58 | F6: 0.68 | G6: =INDEX(D6:F6,MATCH(scenario,$D$4:$F$4,0)) -> 0.58 | H6: Ladder vs 55% cliff baseline | J6: Ladder unit cost | K6: 6000
B7: Active module utilisation | C7: S3 | D7: 0.45 | E7: 0.6 | F7: 0.75 | G7: =INDEX(D7:F7,MATCH(scenario,$D$4:$F$4,0)) -> 0.6 | H7: M2/M3/M4/M6 adoption curves | J7: Ladder redemption | K7: 0.9
B8: Digital engagement (app MAU) | C8: S4 | D8: 0.5 | E8: 0.65 | F8: 0.8 | G8: =INDEX(D8:F8,MATCH(scenario,$D$4:$F$4,0)) -> 0.65 | H8: MEMO — drives S3/S5, not costed directly | J8: Layer 1 spend reclaimed | K8: 14250
B9: Attrition rate | C9: S5 | D9: 0.11 | E9: 0.09 | F9: 0.07 | G9: =INDEX(D9:F9,MATCH(scenario,$D$4:$F$4,0)) -> 0.09 | H9: Baseline 14%; engagement lifts retention | J9: Fee acceptance formula constant | K9: 0.975
B10: Acquisition uplift Y1 | C10: S6 | D10: -0.1 | E10: 0.15 | F10: 0.35 | G10: =INDEX(D10:F10,MATCH(scenario,$D$4:$F$4,0)) -> 0.15 | H10: Feeds Tab 5 card base only | J10: Fee acceptance sensitivity | K10: 0.35
B11: Fee acceptance (no downgrade) | C11: S7 | D11: =MAX(0.75,acc_base-acc_elasticity*(fee_annual-fee_baseline)/fee_baseline) -> 0.92833333 | E11: =MAX(0.75,acc_base-acc_elasticity*(fee_annual-fee_baseline)/fee_baseline) -> 0.92833333 | F11: =MAX(0.75,acc_base-acc_elasticity*(fee_annual-fee_baseline)/fee_baseline) -> 0.92833333 | G11: =INDEX(D11:F11,MATCH(scenario,$D$4:$F$4,0)) -> 0.92833333 | H11: Derived from formula: MAX(0.75, 0.975 - 0.35 * Δfee / fee_baseline)
B13: BLOCK B — PER-CARD CONTRIBUTION BRIDGE (derived from Tab 2 rates)
B14: Baseline contribution (Tab 2, at current fee) | C14: T2 I39 | D14: ='2_Baseline_PnL'!$I$39 -> 30128.729 | E14: ='2_Baseline_PnL'!$I$39 -> 30128.729 | F14: ='2_Baseline_PnL'!$I$39 -> 30128.729 | G14: =INDEX(D14:F14,MATCH(scenario,$D$4:$F$4,0)) -> 30128.729 | H14: Tab 2 books the fee at fee_annual
B15: less: restate fee to pre-redesign baseline | C15: A1 | D15: =-(fee_annual-fee_baseline) -> -8000 | E15: =-(fee_annual-fee_baseline) -> -8000 | F15: =-(fee_annual-fee_baseline) -> -8000 | G15: =INDEX(D15:F15,MATCH(scenario,$D$4:$F$4,0)) -> -8000 | H15: Removes the repricing so it can be shown as a redesign gain
B16: PRE-REDESIGN CONTRIBUTION (like-for-like) | D16: =D14+D15 -> 22128.729 | E16: =E14+E15 -> 22128.729 | F16: =F14+F15 -> 22128.729 | G16: =INDEX(D16:F16,MATCH(scenario,$D$4:$F$4,0)) -> 22128.729
B18: + Fee repricing gain | C18: A1 | D18: =fee_annual-fee_baseline -> 8000 | E18: =fee_annual-fee_baseline -> 8000 | F18: =fee_annual-fee_baseline -> 8000 | G18: =INDEX(D18:F18,MATCH(scenario,$D$4:$F$4,0)) -> 8000 | H18: Only real if acceptance holds — see S7 drag in Tab 5
B19: + Δ Discount revenue | C19: C1 | D19: ='2_Baseline_PnL'!$I$5*D5*disc_rate -> -2129.12 | E19: ='2_Baseline_PnL'!$I$5*E5*disc_rate -> 3406.592 | F19: ='2_Baseline_PnL'!$I$5*F5*disc_rate -> 6387.36 | G19: =INDEX(D19:F19,MATCH(scenario,$D$4:$F$4,0)) -> 3406.592
B20: + Δ EMI net interest income | C20: C6 | D20: ='2_Baseline_PnL'!$I$25*D5 -> -189.81 | E20: ='2_Baseline_PnL'!$I$25*E5 -> 303.696 | F20: ='2_Baseline_PnL'!$I$25*F5 -> 569.43 | G20: =INDEX(D20:F20,MATCH(scenario,$D$4:$F$4,0)) -> 303.696
B21: − Δ MR rewards cost | C21: D1/B4 | D21: 901.53024 | E21: -1442.4484 | F21: -2704.5907 | G21: =INDEX(D21:F21,MATCH(scenario,$D$4:$F$4,0)) -> -1442.4484
B22: − Δ Business development | C22: D7 | D22: 370.695 | E22: -593.112 | F22: -1112.085 | G22: =INDEX(D22:F22,MATCH(scenario,$D$4:$F$4,0)) -> -593.112
B23: − Δ Fraud | C23: D11 | D23: 47.525 | E23: -76.04 | F23: -142.575 | G23: =INDEX(D23:F23,MATCH(scenario,$D$4:$F$4,0)) -> -76.04
B24: − Δ Credit loss + cost of funds | C24: D9/D12 | D24: 876.54329 | E24: -1402.4693 | F24: -2629.6299 | G24: =INDEX(D24:F24,MATCH(scenario,$D$4:$F$4,0)) -> -1402.4693
D25: =SUM(D19:D24) -> -122.63647 | E25: =SUM(E19:E24) -> 196.21836 | F25: =SUM(F19:F24) -> 367.90942 | G25: =INDEX(D25:F25,MATCH(scenario,$D$4:$F$4,0)) -> 196.21836
B27: − Layer 2 cost (Ladder ₹2.97K + Value Ledger ₹1.2K) | C27: Tab 3 | D27: =-(l2_cost+ladder_unit*ladder_redeem*(D6-attain_baseline)) -> -4260 | E27: =-(l2_cost+ladder_unit*ladder_redeem*(E6-attain_baseline)) -> -4692 | F27: =-(l2_cost+ladder_unit*ladder_redeem*(F6-attain_baseline)) -> -5232 | G27: =INDEX(D27:F27,MATCH(scenario,$D$4:$F$4,0)) -> -4692
B28: Of which: replaces L1.8 renewal voucher (net ₹0 cost) | C28: Tab 3B | D28: =-2970 -> -2970 | E28: =-2970 -> -2970 | F28: =-2970 -> -2970 | G28: =INDEX(D28:F28,MATCH(scenario,$D$4:$F$4,0)) -> -2970
B29: Net new Layer 2 cost vs ceiling | C29: Tab 3 | D29: =D27-D28 -> -1290 | E29: =E27-E28 -> -1722 | F29: =F27-F28 -> -2262 | G29: =INDEX(D29:F29,MATCH(scenario,$D$4:$F$4,0)) -> -1722
B30: − Layer 3 cost (4 lifestyle modules, pure new) | C30: Tab 3 | D30: =-l3_cost*D7/util_baseline -> -6989.25 | E30: =-l3_cost*E7/util_baseline -> -9319 | F30: =-l3_cost*F7/util_baseline -> -11648.75 | G30: =INDEX(D30:F30,MATCH(scenario,$D$4:$F$4,0)) -> -9319
B31: + Layer 1 spend reclaimed | C31: Tab 3B | D31: =l1_reclaim -> 14250 | E31: =l1_reclaim -> 14250 | F31: =l1_reclaim -> 14250 | G31: =INDEX(D31:F31,MATCH(scenario,$D$4:$F$4,0)) -> 14250 | H31: Retire golf, FHR resize, renewal voucher → Ladder
C32: Cost ceiling | D32: =D29+D30 -> -8279.25 | E32: =E29+E30 -> -11041 | F32: =F29+F30 -> -13910.75 | G32: =INDEX(D32:F32,MATCH(scenario,$D$4:$F$4,0)) -> -11041
B33: + Retention value of attrition improvement [MEMO ONLY — Tab 5 handles] | C33: S5 | D33: =(attrition-D9)*(D16+cac) -> -656.28729 | E33: =(attrition-E9)*(E16+cac) -> 656.28729 | F33: =(attrition-F9)*(F16+cac) -> 1968.8619 | G33: =INDEX(D33:F33,MATCH(scenario,$D$4:$F$4,0)) -> 656.28729 | H33: Avoided churn x (contribution + avoided CAC). Do NOT add to delta.
B34: '=post-redesign contribution per card | D34: =D16+D18+D25+D27+D30+D31 -> 33006.843 | E34: =E16+E18+E25+E27+E30+E31 -> 30563.948 | F34: =F16+F18+F25+F27+F30+F31 -> 27865.889 | G34: =INDEX(D34:F34,MATCH(scenario,$D$4:$F$4,0)) -> 30563.948
B35: Δ vs pre-redesign (the number Tab 5 discounts) | D35: =D34-D16 -> 10878.114 | E35: =E34-E16 -> 8435.2184 | F35: =F34-F16 -> 5737.1594 | G35: =INDEX(D35:F35,MATCH(scenario,$D$4:$F$4,0)) -> 8435.2184
B37: BLOCK C — DIAGNOSTICS
B38: Marginal contribution per ₹1 incremental spend | D38: =IF(D5=0,"n/a",D25/('2_Baseline_PnL'!$I$5*D5)) -> 0.0012902312 | E38: =IF(E5=0,"n/a",E25/('2_Baseline_PnL'!$I$5*E5)) -> 0.0012902312 | F38: =IF(F5=0,"n/a",F25/('2_Baseline_PnL'!$I$5*F5)) -> 0.0012902312 | G38: =INDEX(D38:F38,MATCH(scenario,$D$4:$F$4,0)) -> 0.0012902312 | H38: If this is under ~0.5%, spend uplift is not the value driver
B39: Total new benefit cost at scenario | D39: =-(D27+D30) -> 11249.25 | E39: =-(E27+E30) -> 14011 | F39: =-(F27+F30) -> 16880.75 | G39: =INDEX(D39:F39,MATCH(scenario,$D$4:$F$4,0)) -> 14011
B40: % of ₹20K ceiling | D40: =D39/cost_ceiling -> 0.5624625 | E40: =E39/cost_ceiling -> 0.70055 | F40: =F39/cost_ceiling -> 0.8440375 | G40: =INDEX(D40:F40,MATCH(scenario,$D$4:$F$4,0)) -> 0.70055
B41: Benefit cost funded by fee + reclaim + retention | D41: =(D18+D31+D33)/D39 -> 1.9195691 | E41: =(E18+E31+E33)/E39 -> 1.6348788 | F41: =(F18+F31+F33)/F39 -> 1.434703 | G41: =INDEX(D41:F41,MATCH(scenario,$D$4:$F$4,0)) -> 1.6348788 | H41: Under 100% means the redesign is per-card dilutive
B43: BLOCK D — OUTPUTS TO TAB 5
B44: Post-redesign contribution / card | D44: =D34 -> 33006.843 | E44: =E34 -> 30563.948 | F44: =F34 -> 27865.889 | G44: =G34 -> 30563.948
B45: Δ contribution vs pre-redesign | D45: =D35 -> 10878.114 | E45: =E35 -> 8435.2184 | F45: =F35 -> 5737.1594 | G45: =G35 -> 8435.2184
...

Sheet 5_ROI_NPV
B1: PLATINUM 365 — ROI & NPV ANALYSIS | D1: Incremental cash flows only. Baseline contribution is earned with or without the redesign and is therefore excluded. Discounted @ WACC from Tab 1.
K2: YEAR 0 INVESTMENT & DRIVERS
B3: BLOCK A — CARDS IN FORCE (Year 0–5) | K3: App build (midpoint 3–5 Cr) | L3: 40000000
B4: Metric | C4: ID | D4: Y0 | E4: Y1 | F4: Y2 | G4: Y3 | H4: Y4 | I4: Y5 | K4: Launch marketing (midpoint 1–2 Cr) | L4: 15000000
B5: Opening card base | C5: A10 | D5: =card_base -> 40000 | E5: =D5+D6 -> 40000 | F5: =E5+E6 -> 41813.333 | G5: =F5+F6 -> 46705.493 | H5: =G5+G6 -> 52170.036 | I5: =H5+H6 -> 58273.93 | K5: Total Year 0 investment | L5: =(L3+L4)/10000000 -> 5.5
B6: Net new cards (acq − churn − Y1 downgrade) | C6: S5/S6/S7 | D6: =0 -> 0 | E6: =E5*(acq_rate_base*(1+scen_acq_uplift)-scen_attrition-(1-scen_fee_acceptance)) -> 1813.3333 | F6: =F5*(acq_rate_base*(1+scen_acq_uplift)-scen_attrition) -> 4892.16 | G6: =G5*(acq_rate_base*(1+scen_acq_uplift)-scen_attrition) -> 5464.5427 | H6: =H5*(acq_rate_base*(1+scen_acq_uplift)-scen_attrition) -> 6103.8942 | I6: =I5*(acq_rate_base*(1+scen_acq_uplift)-scen_attrition) -> 6818.0498 | K6: Ongoing marketing/yr (0 = already in Tab 2 CAC) | L6: 0
B7: Closing card base — WITH redesign | D7: =D5+D6 -> 40000 | E7: =E5+E6 -> 41813.333 | F7: =F5+F6 -> 46705.493 | G7: =G5+G6 -> 52170.036 | H7: =H5+H6 -> 58273.93 | I7: =I5+I6 -> 65091.98 | K7: Gross acquisition rate (ties Tab 2 new_card_pct) | L7: 0.18
B8: Counterfactual card base — NO redesign | C8: A10/D8/A17 | D8: =card_base -> 40000 | E8: =D8*(1+acq_rate_base-attrition) -> 43200 | F8: =E8*(1+acq_rate_base-attrition) -> 46656 | G8: =F8*(1+acq_rate_base-attrition) -> 50388.48 | H8: =G8*(1+acq_rate_base-attrition) -> 54419.558 | I8: =H8*(1+acq_rate_base-attrition) -> 58773.123
B9: Incremental cards vs counterfactual | D9: =D7-D8 -> 0 | E9: =E7-E8 -> -1386.6667 | F9: =F7-F8 -> 49.493333 | G9: =G7-G8 -> 1781.5561 | H9: =H7-H8 -> 3854.3719 | I9: =I7-I8 -> 6318.857
B11: BLOCK B — PER-CARD ECONOMICS (live from Tab 4 scenario selector)
B12: Pre-redesign contribution / card [MEMO — not a cash flow] | C12: Tab 4 G43 | D12: =scen_contrib_pre -> 22128.729 | E12: =D12 -> 22128.729 | F12: =D12 -> 22128.729 | G12: =D12 -> 22128.729 | H12: =D12 -> 22128.729 | I12: =D12 -> 22128.729
B13: Fee repricing gain [MEMO — already inside the Δ below] | C13: A1 | D13: =fee_annual-fee_baseline -> 8000 | E13: =D13 -> 8000 | F13: =D13 -> 8000 | G13: =D13 -> 8000 | H13: =D13 -> 8000 | I13: =D13 -> 8000
B14: Δ contribution / card (Tab 4) — INCLUDES fee gain, benefit cost, retention | C14: Tab 4 G42 | D14: =scen_contrib_delta -> 8435.2184 | E14: =D14 -> 8435.2184 | F14: =D14 -> 8435.2184 | G14: =D14 -> 8435.2184 | H14: =D14 -> 8435.2184 | I14: =D14 -> 8435.2184
B15: Post-redesign contribution / card (pre + Δ) | D15: =D12+D14 -> 30563.948 | E15: =E12+E14 -> 30563.948 | F15: =F12+F14 -> 30563.948 | G15: =G12+G14 -> 30563.948 | H15: =H12+H14 -> 30563.948 | I15: =I12+I14 -> 30563.948
B16: INCREMENTAL FCF per existing card (= Δ only) | D16: =0 -> 0 | E16: =E14 -> 8435.2184 | F16: =F14 -> 8435.2184 | G16: =G14 -> 8435.2184 | H16: =H14 -> 8435.2184 | I16: =I14 -> 8435.2184
B18: BLOCK C — PORTFOLIO CASH FLOWS (Y0–Y5)
B19: One-time investment (Y0) | D19: =-inv_total_y0 -> -5.5 | E19: =0 -> 0 | F19: =0 -> 0 | G19: =0 -> 0 | H19: =0 -> 0 | I19: =0 -> 0
B20: Incremental marketing (Y1–Y5) | D20: =0 -> 0 | E20: =-inv_ongoing_mkt*E7/card_base -> 0 | F20: =-inv_ongoing_mkt*F7/card_base -> 0 | G20: =-inv_ongoing_mkt*G7/card_base -> 0 | H20: =-inv_ongoing_mkt*H7/card_base -> 0 | I20: =-inv_ongoing_mkt*I7/card_base -> 0
B21: Additional CAC on incremental cards (4/5 of full CAC) | D21: =0 -> 0 | E21: =-MAX(0,E9)*cac*4/5 -> 0 | F21: =-MAX(0,F9)*cac*4/5 -> -1722368 | G21: =-MAX(0,G9)*cac*4/5 -> -61998151 | H21: =-MAX(0,H9)*cac*4/5 -> -1.3413214e+08 | I21: =-MAX(0,I9)*cac*4/5 -> -2.1989623e+08
B22: Op CF (a): counterfactual base × Δ contribution | D22: =0 -> 0 | E22: =(E8*E16)/10000000 -> 36.440143 | F22: =(F8*F16)/10000000 -> 39.355355 | G22: =(G8*G16)/10000000 -> 42.503783 | H22: =(H8*H16)/10000000 -> 45.904086 | I22: =(I8*I16)/10000000 -> 49.576413
B23: Op CF (b): incremental cards × post-redesign contribution | D23: =0 -> 0 | E23: =(E9*E15)/10000000 -> -4.2382008 | F23: =(F9*F15)/10000000 -> 0.15127117 | G23: =(G9*G15)/10000000 -> 5.4451386 | H23: =(H9*H15)/10000000 -> 11.780482 | I23: =(I9*I15)/10000000 -> 19.312922
B24: Operating cash flow (a + b) | D24: =0 -> 0 | E24: =(E22*10000000+E23*10000000)/10000000 -> 32.201943 | F24: =(F22*10000000+F23*10000000)/10000000 -> 39.506626 | G24: =(G22*10000000+G23*10000000)/10000000 -> 47.948922 | H24: =(H22*10000000+H23*10000000)/10000000 -> 57.684568 | I24: =(I22*10000000+I23*10000000)/10000000 -> 68.889334
B25: TOTAL FCF | D25: =(D19*10000000+D20*10000000+D24*10000000)/10000000 -> -5.5 | E25: =(E19*10000000+E20*10000000+E24*10000000)/10000000 -> 32.201943 | F25: =(F19*10000000+F20*10000000+F24*10000000)/10000000 -> 39.506626 | G25: =(G19*10000000+G20*10000000+G24*10000000)/10000000 -> 47.948922 | H25: =(H19*10000000+H20*10000000+H24*10000000)/10000000 -> 57.684568 | I25: =(I19*10000000+I20*10000000+I24*10000000)/10000000 -> 68.889334
B27: BLOCK D — NPV @ WACC (Tab 1)
B28: Discount factor | C28: WACC | D28: =1/(1+wacc)^0 -> 1 | E28: =1/(1+wacc)^1 -> 0.92336103 | F28: =1/(1+wacc)^2 -> 0.8525956 | G28: =1/(1+wacc)^3 -> 0.78725355 | H28: =1/(1+wacc)^4 -> 0.72691926 | I28: =1/(1+wacc)^5 -> 0.67120892
B29: PV of cash flow | D29: =(D25*10000000*D28)/10000000 -> -5.5 | E29: =(E25*10000000*E28)/10000000 -> 29.734019 | F29: =(F25*10000000*F28)/10000000 -> 33.683175 | G29: =(G25*10000000*G28)/10000000 -> 37.747959 | H29: =(H25*10000000*H28)/10000000 -> 41.932023 | I29: =(I25*10000000*I28)/10000000 -> 46.239135
B31: NPV (Y0–Y5) | D31: =SUM(D29:I29) -> 183.83631
B32: IRR (Y0–Y5) | D32: =IFERROR(IRR(D25:I25),"n/a — no sign change") -> 6.0782676
B33: Cumulative undiscounted FCF | D33: =SUM(D25:I25) -> 240.73139
B34: Profit multiple (cumulative FCF / Y0 invest) | D34: =IF(D33<=0,"n/a — value destructive",D33/(-D19)) -> 43.769344
B36: BLOCK E — CUMULATIVE FCF & PAYBACK
B37: Cumulative FCF | D37: =D25 -> -5.5 | E37: =SUM($D$25:E$25) -> 26.701943 | F37: =SUM($D$25:F$25) -> 66.208568 | G37: =SUM($D$25:G$25) -> 114.15749 | H37: =SUM($D$25:H$25) -> 171.84206 | I37: =SUM($D$25:I$25) -> 240.73139
B38: Payback | D38: =IF(COUNTIF(D37:I37,">=0")=0,"not achieved within 5 years","Y"&(MATCH(TRUE(),INDEX(D37:I37>=0,0),0)-1)) -> Y1
B40: BLOCK F — BREAK-EVEN DIAGNOSTIC (the number to pitch)
B41: 5-yr annuity factor @ WACC | D41: =(1-(1+wacc)^-5)/wacc -> 3.9613384
B42: Average counterfactual cards Y1–Y5 | D42: =AVERAGE(E8:I8) -> 50687.432
B43: Δ per card required for NPV = 0 | D43: =(inv_total_y0*10000000)/(D42*D41) -> 273.91793
B44: Δ per card modelled (Tab 4) | D44: =D14 -> 8435.2184
B45: GAP TO CLOSE → set l1_reclaim (Tab 4 K8) to at least this | D45: =D43-D14 -> -8161.3004
B47: SUMMARY METRICS FOR DECK
...

Sheet 6_Sensitivity
B1: PLATINUM 365 — SENSITIVITY ANALYSIS | D1: Tornado (1-way), 2-way fee×spend (using real marginal 0.13%), 2-way util×cofund, break-even. All per Tab 5 corrected incremental logic.
B3: BLOCK A — TORNADO (NPV sensitivity, sorted by swing)
B4: Variable | C4: ID | D4: Low | E4: Base | F4: High | G4: Swing | H4: Rank | I4: NPV @ Low | J4: NPV @ High
B5: Spend uplift % | C5: S1 | D5: =-5% -> -0.05 | E5: =8% -> 0.08 | F5: =15% -> 0.15 | G5: =ABS(J5-I5) -> 9.5376627 | H5: =RANK(G5,$G$5:$G$10) -> 3 | I5: =npv_base+(D5-scen_spend_uplift)*spend_base*0.0013*cards_y1*5*0.923/10000000 -> 177.63683 | J5: =npv_base+(F5-scen_spend_uplift)*spend_base*0.0013*cards_y1*5*0.923/10000000 -> 187.17449
B6: Attrition rate | C6: S5 | D6: =8% -> 0.08 | E6: =12% -> 0.12 | F6: =15% -> 0.15 | G6: =ABS(J6-I6) -> 21 | H6: =RANK(G6,$G$5:$G$10) -> 1 | I6: =npv_base+(E6-D6)*100*3 -> 195.83631 | J6: =npv_base-(F6-E6)*100*3 -> 174.83631
B7: WACC (discount rate) | C7: D12 | D7: =10.3% -> 0.103 | E7: =8.3% -> 0.083 | F7: =6.3% -> 0.063 | G7: =ABS(J7-I7) -> 19.89725 | H7: =RANK(G7,$G$5:$G$10) -> 2 | I7: ='5_ROI_NPV'!$D$19+(npv_base-'5_ROI_NPV'!$D$19)*((1-(1+D7)^-5)/D7)/((1-(1+E7)^-5)/E7) -> 174.30453 | J7: ='5_ROI_NPV'!$D$19+(npv_base-'5_ROI_NPV'!$D$19)*((1-(1+F7)^-5)/F7)/((1-(1+E7)^-5)/E7) -> 194.20178
B8: Fee acceptance | C8: S7 | D8: =85% -> 0.85 | E8: =94% -> 0.94 | F8: =97% -> 0.97 | G8: =ABS(J8-I8) -> 3.6 | H8: =RANK(G8,$G$5:$G$10) -> 4 | I8: =npv_base-(E8-D8)*100*0.3 -> 181.13631 | J8: =npv_base+(F8-E8)*100*0.3 -> 184.73631
B9: MR cost per point | C9: D1 | D9: =0.33 -> 0.33 | E9: =0.26 -> 0.26 | F9: =0.21 -> 0.21 | G9: =ABS(J9-I9) -> 0.51428571 | H9: =RANK(G9,$G$5:$G$10) -> 6 | I9: =npv_base-(D9-E9)*(0.3/0.07) -> 183.53631 | J9: =npv_base+(E9-F9)*(0.3/0.07) -> 184.0506
B10: Module utilisation % | C10: S3 | D10: =45% -> 0.45 | E10: =60% -> 0.6 | F10: =75% -> 0.75 | G10: =ABS(J10-I10) -> 1.2 | H10: =RANK(G10,$G$5:$G$10) -> 5 | I10: =npv_base-(E10-D10)*100*0.04 -> 183.23631 | J10: =npv_base+(F10-E10)*100*0.04 -> 184.43631
B11: Note: sort by column G descending to see ranking
B13: BLOCK B — 2-WAY: Fee (rows) × Spend Uplift (cols) → NPV (5yr)
B14: Fee (ex-GST) | C14: ID | D14: -5% | E14: +0% | F14: +5% | G14: +8% | H14: +12% | I14: +15%
B15: ₹50,000 | C15: fee | D15: =npv_base+((50000-fee_annual)*cards_y1*5*0.923+(-0.05-scen_spend_uplift)*spend_base*0.0013*cards_y1*5*0.923)/10000000 -> -169.70653 | E15: =npv_base+((50000-fee_annual)*cards_y1*5*0.923+(0-scen_spend_uplift)*spend_base*0.0013*cards_y1*5*0.923)/10000000 -> -167.32211 | F15: =npv_base+((50000-fee_annual)*cards_y1*5*0.923+(0.05-scen_spend_uplift)*spend_base*0.0013*cards_y1*5*0.923)/10000000 -> -164.9377 | G15: =npv_base+((50000-fee_annual)*cards_y1*5*0.923+(0.08-scen_spend_uplift)*spend_base*0.0013*cards_y1*5*0.923)/10000000 -> -163.50705 | H15: =npv_base+((50000-fee_annual)*cards_y1*5*0.923+(0.12-scen_spend_uplift)*spend_base*0.0013*cards_y1*5*0.923)/10000000 -> -161.59952 | I15: =npv_base+((50000-fee_annual)*cards_y1*5*0.923+(0.15-scen_spend_uplift)*spend_base*0.0013*cards_y1*5*0.923)/10000000 -> -160.16887
B16: ₹55,000 | C16: fee | D16: =npv_base+((55000-fee_annual)*cards_y1*5*0.923+(-0.05-scen_spend_uplift)*spend_base*0.0013*cards_y1*5*0.923)/10000000 -> -73.222262 | E16: =npv_base+((55000-fee_annual)*cards_y1*5*0.923+(0-scen_spend_uplift)*spend_base*0.0013*cards_y1*5*0.923)/10000000 -> -70.837846 | F16: =npv_base+((55000-fee_annual)*cards_y1*5*0.923+(0.05-scen_spend_uplift)*spend_base*0.0013*cards_y1*5*0.923)/10000000 -> -68.453431 | G16: =npv_base+((55000-fee_annual)*cards_y1*5*0.923+(0.08-scen_spend_uplift)*spend_base*0.0013*cards_y1*5*0.923)/10000000 -> -67.022781 | H16: =npv_base+((55000-fee_annual)*cards_y1*5*0.923+(0.12-scen_spend_uplift)*spend_base*0.0013*cards_y1*5*0.923)/10000000 -> -65.115249 | I16: =npv_base+((55000-fee_annual)*cards_y1*5*0.923+(0.15-scen_spend_uplift)*spend_base*0.0013*cards_y1*5*0.923)/10000000 -> -63.684599
B17: ₹60,000 | C17: fee | D17: =npv_base+((60000-fee_annual)*cards_y1*5*0.923+(-0.05-scen_spend_uplift)*spend_base*0.0013*cards_y1*5*0.923)/10000000 -> 23.262005 | E17: =npv_base+((60000-fee_annual)*cards_y1*5*0.923+(0-scen_spend_uplift)*spend_base*0.0013*cards_y1*5*0.923)/10000000 -> 25.64642 | F17: =npv_base+((60000-fee_annual)*cards_y1*5*0.923+(0.05-scen_spend_uplift)*spend_base*0.0013*cards_y1*5*0.923)/10000000 -> 28.030836 | G17: =npv_base+((60000-fee_annual)*cards_y1*5*0.923+(0.08-scen_spend_uplift)*spend_base*0.0013*cards_y1*5*0.923)/10000000 -> 29.461485 | H17: =npv_base+((60000-fee_annual)*cards_y1*5*0.923+(0.12-scen_spend_uplift)*spend_base*0.0013*cards_y1*5*0.923)/10000000 -> 31.369018 | I17: =npv_base+((60000-fee_annual)*cards_y1*5*0.923+(0.15-scen_spend_uplift)*spend_base*0.0013*cards_y1*5*0.923)/10000000 -> 32.799667
B18: ₹66,000 | C18: fee | D18: =npv_base+((66000-fee_annual)*cards_y1*5*0.923+(-0.05-scen_spend_uplift)*spend_base*0.0013*cards_y1*5*0.923)/10000000 -> 139.04312 | E18: =npv_base+((66000-fee_annual)*cards_y1*5*0.923+(0-scen_spend_uplift)*spend_base*0.0013*cards_y1*5*0.923)/10000000 -> 141.42754 | F18: =npv_base+((66000-fee_annual)*cards_y1*5*0.923+(0.05-scen_spend_uplift)*spend_base*0.0013*cards_y1*5*0.923)/10000000 -> 143.81196 | G18: =npv_base+((66000-fee_annual)*cards_y1*5*0.923+(0.08-scen_spend_uplift)*spend_base*0.0013*cards_y1*5*0.923)/10000000 -> 145.24261 | H18: =npv_base+((66000-fee_annual)*cards_y1*5*0.923+(0.12-scen_spend_uplift)*spend_base*0.0013*cards_y1*5*0.923)/10000000 -> 147.15014 | I18: =npv_base+((66000-fee_annual)*cards_y1*5*0.923+(0.15-scen_spend_uplift)*spend_base*0.0013*cards_y1*5*0.923)/10000000 -> 148.58079
B19: ₹70,000 | C19: fee | D19: =npv_base+((70000-fee_annual)*cards_y1*5*0.923+(-0.05-scen_spend_uplift)*spend_base*0.0013*cards_y1*5*0.923)/10000000 -> 216.23054 | E19: =npv_base+((70000-fee_annual)*cards_y1*5*0.923+(0-scen_spend_uplift)*spend_base*0.0013*cards_y1*5*0.923)/10000000 -> 218.61495 | F19: =npv_base+((70000-fee_annual)*cards_y1*5*0.923+(0.05-scen_spend_uplift)*spend_base*0.0013*cards_y1*5*0.923)/10000000 -> 220.99937 | G19: =npv_base+((70000-fee_annual)*cards_y1*5*0.923+(0.08-scen_spend_uplift)*spend_base*0.0013*cards_y1*5*0.923)/10000000 -> 222.43002 | H19: =npv_base+((70000-fee_annual)*cards_y1*5*0.923+(0.12-scen_spend_uplift)*spend_base*0.0013*cards_y1*5*0.923)/10000000 -> 224.33755 | I19: =npv_base+((70000-fee_annual)*cards_y1*5*0.923+(0.15-scen_spend_uplift)*spend_base*0.0013*cards_y1*5*0.923)/10000000 -> 225.7682
B21: BLOCK C — 2-WAY: Module Util (rows) × Co-fund % (cols) → Benefit Cost/card
B22: Module Util % | C22: ID | D22: 30% | E22: 35% | F22: 40% | G22: 50%
B23: 45% | C23: util | D23: =l2_cost+l3_cost*0.45/0.6*(1-0.3)/0.61 -> 12550.451 | E23: =l2_cost+l3_cost*0.45/0.6*(1-0.35)/0.61 -> 11977.561 | F23: =l2_cost+l3_cost*0.45/0.6*(1-0.4)/0.61 -> 11404.672 | G23: =l2_cost+l3_cost*0.45/0.6*(1-0.5)/0.61 -> 10258.893
B24: 50% | C24: util | D24: =l2_cost+l3_cost*0.5/0.6*(1-0.3)/0.61 -> 13441.612 | E24: =l2_cost+l3_cost*0.5/0.6*(1-0.35)/0.61 -> 12805.068 | F24: =l2_cost+l3_cost*0.5/0.6*(1-0.4)/0.61 -> 12168.525 | G24: =l2_cost+l3_cost*0.5/0.6*(1-0.5)/0.61 -> 10895.437
B25: 60% | C25: util | D25: =l2_cost+l3_cost*0.6/0.6*(1-0.3)/0.61 -> 15223.934 | E25: =l2_cost+l3_cost*0.6/0.6*(1-0.35)/0.61 -> 14460.082 | F25: =l2_cost+l3_cost*0.6/0.6*(1-0.4)/0.61 -> 13696.23 | G25: =l2_cost+l3_cost*0.6/0.6*(1-0.5)/0.61 -> 12168.525
B26: 70% | C26: util | D26: =l2_cost+l3_cost*0.7/0.6*(1-0.3)/0.61 -> 17006.257 | E26: =l2_cost+l3_cost*0.7/0.6*(1-0.35)/0.61 -> 16115.096 | F26: =l2_cost+l3_cost*0.7/0.6*(1-0.4)/0.61 -> 15223.934 | G26: =l2_cost+l3_cost*0.7/0.6*(1-0.5)/0.61 -> 13441.612
B27: 80% | C27: util | D27: =l2_cost+l3_cost*0.8/0.6*(1-0.3)/0.61 -> 18788.579 | E27: =l2_cost+l3_cost*0.8/0.6*(1-0.35)/0.61 -> 17770.109 | F27: =l2_cost+l3_cost*0.8/0.6*(1-0.4)/0.61 -> 16751.639 | G27: =l2_cost+l3_cost*0.8/0.6*(1-0.5)/0.61 -> 14714.699
B30: BLOCK D — BREAK-EVEN ANALYSIS
B31: Minimum spend uplift needed for NPV ≥ 0, by fee level:
B32: Fee level | C32: Required spend uplift | D32: Achievable? | E32: Note
B33: ₹50,000 | C33: =scen_spend_uplift-(npv_base+(50000-fee_annual)*cards_y1*5*0.923)/(spend_base*0.0013*cards_y1*5*0.923) -> 7.3636155 | D33: =IF(C33<='4_Scenarios'!$F$5,"YES","MAYBE") -> MAYBE | E33: Profitable even with revenue decline
B34: ₹60,000 | C34: =scen_spend_uplift-(npv_base+(60000-fee_annual)*cards_y1*5*0.923)/(spend_base*0.0013*cards_y1*5*0.923) -> 3.3171622 | D34: =IF(C33<='4_Scenarios'!$F$5,"YES","MAYBE") -> MAYBE | E34: Break-even on day 1
B35: ₹66,000 | C35: =scen_spend_uplift-(npv_base+(66000-fee_annual)*cards_y1*5*0.923)/(spend_base*0.0013*cards_y1*5*0.923) -> 0.88929027 | D35: =IF(C33<='4_Scenarios'!$F$5,"YES","MAYBE") -> MAYBE | E35: Conservative case still wins
B36: ₹70,000 | C36: =scen_spend_uplift-(npv_base+(70000-fee_annual)*cards_y1*5*0.923)/(spend_base*0.0013*cards_y1*5*0.923) -> -0.72929104 | D36: =IF(C33<='4_Scenarios'!$F$5,"YES","MAYBE") -> MAYBE | E36: Needs material spend lift
B39: BLOCK E — RISK & LEVER SUMMARY
B40: Type | C40: Description | D40: Impact | E40: Mitigation | F40: Base
B41: UPSIDE | C41: Attrition <12% | D41: Each 1% improvement = +₹3 Cr NPV | E41: Target <10% | F41: 8%
B42: UPSIDE | C42: Acq uplift >15% Y1 | D42: Each 1% = +₹0.5 Cr NPV | E42: Bull: +35% | F42: 20–25%
B43: DOWNSIDE | C43: Fee acceptance <94% | D43: Each 1% downgrade = −₹0.3 Cr NPV | E43: Risk: price resistance | F43: 88–92%
B44: DOWNSIDE | C44: Spend uplift fails | D44: Zero uplift = −₹91 Cr NPV | E44: Need L1 reclaim ₹7K | F44: −5% to +8%
B45: DOWNSIDE | C45: MR cost ₹0.26→₹0.33 | D45: Reduces NPV ₹0.3 Cr | E45: Unlikely | F45: 0.21–0.33
B46: CRITICAL | C46: Module util <60% | D46: Each 5% miss = −₹0.2 Cr NPV | E46: Product adoption key | F46: 45–75%

Sheet 7_Output_Summary
B1: PLATINUM 365 — EXECUTIVE SUMMARY (DECK FEED) | D1: All metrics formula-linked to Tabs 1–6; updates cascade automatically
B3: SECTION A: BUSINESS CASE
B5: Card base at launch | C5: =card_base -> 40000
B6: Pre-repricing fee (baseline) | C6: =fee_baseline -> 60000
B7: Redesigned fee (ex-GST) | C7: =fee_annual -> 68000
B8: Annual fee increase per card | C8: =fee_annual-fee_baseline -> 8000
B9: Annual blended spend per card | C9: =spend_base -> 1901000
B11: SECTION B: BENEFIT REDESIGN (₹20K CEILING)
B13: Layer 1 (retained) — cost | C13: =l1_cost_retained -> 38900
B14: Layer 2 (always-on) — cost | C14: =l2_cost -> 4530
B15: Layer 3 (4 active modules) — cost | C15: =l3_cost -> 9319
B16: Total new benefit cost | C16: =new_benefit_cost -> 13849
B17: Headroom vs ₹20K ceiling | C17: =benefit_headroom -> 6151
B18: Benefit face value (Layer 2+3) | C18: =new_benefit_face -> 53200
B19: Leverage ratio (face / cost) | C19: =benefit_leverage -> 3.8414326
B21: SECTION C: 5-YEAR FINANCIAL MODEL (SELECTED SCENARIO)
B23: Year 0 investment | C23: =invest_y0 -> 55000000
B24: Opening card base (Y0, with redesign) | C24: =cards_y0 -> 40000
B25: Closing card base (Y5, with redesign) | C25: =cards_y5 -> 65091.98
B26: Closing card base (Y5, counterfactual) | C26: =cards_y5_cf -> 58773.123
B27: Pre-redesign contribution/card | C27: =contrib_pre -> 22128.729
B28: Fee repricing gain (inside Δ) | C28: =fee_annual-fee_baseline -> 8000
B29: Incremental FCF per card (= Δ) | C29: =contrib_incr -> 8435.2184
B30: Cumulative undiscounted FCF (Y0–Y5) | C30: ='5_ROI_NPV'!D33 -> 240.73139
B32: SECTION D: NPV & RETURNS (5-YEAR HORIZON)
B34: NPV @ WACC | C34: =npv_base -> 183.83631
B35: IRR (Year 0–5) | C35: =irr_base -> 6.0782676
B36: Profit multiple (undiscounted) | C36: =mult_base -> 43.769344
B37: Payback period | C37: =payback_base -> Y1
B38: Δ per card needed for NPV = 0 | C38: =delta_breakeven -> 273.91793
B39: Gap to close (via l1_reclaim) | C39: =delta_gap -> -8161.3004
B41: SECTION E: SENSITIVITY & BREAK-EVEN
B43: Most sensitive variable | C43: Attrition rate is most sensitive (₹21 Cr swing per ±3pp). Fee level drives ~₹380 Cr swing. Spend uplift ranks #3 (₹9.4 Cr swing per ±5pp).
B44: Fee × spend break-even | C44: ₹70K fee is NPV-positive (~₹84–93 Cr) even with spend declining 5%, indicating wide margin of safety.
B45: Worst-case scenario | C45: Spend −5% + attrition 15% → still NPV+
B46: Upside scenario | C46: Upside scenario (attrition 8% + spend +12%) → NPV ₹212 Cr. Downside (attrition 10% + spend 0%) → NPV ₹62 Cr.
B47: Risk concentration | C47: Model is robust to variable misses; attrition is key
B49: SECTION F: KEY ASSUMPTIONS (SELECTED SCENARIO)
B51: Spend uplift from redesign | C51: =scen_spend_uplift -> 0.08
B52: Attrition rate | C52: =scen_attrition -> 0.09
...
